package com.gto.gtocore.common.data.machines;

import com.gto.gtocore.GTOCore;
import com.gto.gtocore.api.data.tag.GTOTagPrefix;
import com.gto.gtocore.api.machine.multiblock.GTOPartAbility;
import com.gto.gtocore.api.machine.multiblock.StorageMachine;
import com.gto.gtocore.api.pattern.GTOPredicates;
import com.gto.gtocore.client.renderer.machine.EyeOfHarmonyRenderer;
import com.gto.gtocore.client.renderer.machine.SpaceElevatorRenderer;
import com.gto.gtocore.common.block.GTOFusionCasingBlock;
import com.gto.gtocore.common.data.*;
import com.gto.gtocore.common.machine.multiblock.electric.*;
import com.gto.gtocore.common.machine.multiblock.noenergy.HarmonyMachine;
import com.gto.gtocore.common.machine.multiblock.noenergy.HeatExchangerMachine;
import com.gto.gtocore.common.machine.multiblock.noenergy.NeutronActivatorMachine;
import com.gto.gtocore.utils.MachineUtil;
import com.gto.gtocore.utils.Registries;

import com.gregtechceu.gtceu.GTCEu;
import com.gregtechceu.gtceu.api.GTValues;
import com.gregtechceu.gtceu.api.data.RotationState;
import com.gregtechceu.gtceu.api.data.chemical.ChemicalHelper;
import com.gregtechceu.gtceu.api.data.tag.TagPrefix;
import com.gregtechceu.gtceu.api.machine.MultiblockMachineDefinition;
import com.gregtechceu.gtceu.api.machine.multiblock.CoilWorkableElectricMultiblockMachine;
import com.gregtechceu.gtceu.api.machine.multiblock.PartAbility;
import com.gregtechceu.gtceu.api.machine.multiblock.WorkableElectricMultiblockMachine;
import com.gregtechceu.gtceu.api.machine.multiblock.WorkableMultiblockMachine;
import com.gregtechceu.gtceu.api.pattern.FactoryBlockPattern;
import com.gregtechceu.gtceu.api.pattern.MultiblockShapeInfo;
import com.gregtechceu.gtceu.api.pattern.Predicates;
import com.gregtechceu.gtceu.api.pattern.TraceabilityPredicate;
import com.gregtechceu.gtceu.api.pattern.util.RelativeDirection;
import com.gregtechceu.gtceu.api.recipe.OverclockingLogic;
import com.gregtechceu.gtceu.client.renderer.machine.FusionReactorRenderer;
import com.gregtechceu.gtceu.common.data.*;
import com.gregtechceu.gtceu.common.machine.multiblock.electric.FusionReactorMachine;
import com.gregtechceu.gtceu.utils.FormattingUtil;

import net.minecraft.ChatFormatting;
import net.minecraft.core.BlockPos;
import net.minecraft.core.Direction;
import net.minecraft.network.chat.Component;
import net.minecraft.network.chat.Style;
import net.minecraft.server.MinecraftServer;
import net.minecraft.world.entity.Entity;
import net.minecraft.world.entity.item.ItemEntity;
import net.minecraft.world.entity.player.Player;
import net.minecraft.world.item.ItemStack;
import net.minecraft.world.level.Level;
import net.minecraft.world.level.block.Block;
import net.minecraft.world.level.block.Blocks;
import net.minecraft.world.level.block.DirectionalBlock;
import net.minecraft.world.phys.AABB;

import com.hepdd.gtmthings.data.CustomMachines;

import java.util.ArrayList;
import java.util.List;
import java.util.Locale;
import java.util.Objects;

import static com.gto.gtocore.api.registries.GTORegistration.REGISTRATE;

@SuppressWarnings("unused")
public class AdvancedMultiBlockMachineA {

    public static void init() {}

    public final static MultiblockMachineDefinition GREENHOUSE = REGISTRATE.multiblock("greenhouse", GreenhouseMachine::new)
            .rotationState(RotationState.NON_Y_AXIS)
            .allowExtendedFacing(false)
            .recipeType(GTORecipeTypes.GREENHOUSE_RECIPES)
            .tooltips(Component.translatable("gtocore.machine.greenhouse.tooltip.0"))
            .tooltips(Component.translatable("gtocore.machine.greenhouse.tooltip.1"))
            .tooltips(Component.translatable("gtceu.machine.available_recipe_map_1.tooltip",
                    Component.translatable("gtceu.greenhouse")))
            .appearanceBlock(GTBlocks.MACHINE_CASING_ULV)
            .recipeModifier(GTRecipeModifiers.ELECTRIC_OVERCLOCK.apply(OverclockingLogic.NON_PERFECT_OVERCLOCK))
            .pattern((definition) -> FactoryBlockPattern.start()
                    .aisle("0BBB0", "0BBB0", "0BBB0", "0BBB0")
                    .aisle("BBBBB", "B###B", "B###B", "BGGGB")
                    .aisle("BBBBB", "B###B", "B###B", "BGGGB")
                    .aisle("BBBBB", "B###B", "B###B", "BGGGB")
                    .aisle("0BBB0", "0BEB0", "0BBB0", "0BBB0")
                    .where("E", Predicates.controller(Predicates.blocks(definition.get())))
                    .where("G", Predicates.blocks(GTBlocks.CASING_TEMPERED_GLASS.get()))
                    .where("B", Predicates.blocks(GTBlocks.MACHINE_CASING_ULV.get())
                            .setMinGlobalLimited(40)
                            .or(Predicates.autoAbilities(definition.getRecipeTypes()))
                            .or(Predicates.abilities(PartAbility.MAINTENANCE).setExactLimit(1)))
                    .where("#", Predicates.air())
                    .where("0", Predicates.any())
                    .build())
            .workableCasingRenderer(GTCEu.id("block/casings/voltage/ulv/side"), GTCEu.id("block/multiblock/implosion_compressor"))
            .register();

    public final static MultiblockMachineDefinition EYE_OF_HARMONY = REGISTRATE.multiblock("eye_of_harmony", HarmonyMachine::new)
            .rotationState(RotationState.NON_Y_AXIS)
            .allowExtendedFacing(false)
            .recipeType(GTORecipeTypes.COSMOS_SIMULATION_RECIPES)
            .tooltips(Component.translatable("gtocore.machine.eye_of_harmony.tooltip.0"))
            .tooltips(Component.translatable("gtocore.machine.eye_of_harmony.tooltip.1"))
            .tooltips(Component.translatable("gtocore.machine.eye_of_harmony.tooltip.2"))
            .tooltips(Component.translatable("gtocore.machine.eye_of_harmony.tooltip.3"))
            .tooltips(Component.translatable("gtocore.machine.eye_of_harmony.tooltip.4"))
            .tooltips(Component.translatable("gtocore.machine.eye_of_harmony.tooltip.5"))
            .tooltips(Component.translatable("gtocore.machine.eye_of_harmony.tooltip.6"))
            .tooltips(Component.translatable("gtceu.machine.available_recipe_map_1.tooltip",
                    Component.translatable("gtceu.cosmos_simulation")))
            .recipeModifier(HarmonyMachine::recipeModifier)
            .appearanceBlock(GTBlocks.HIGH_POWER_CASING)
            .pattern(definition -> FactoryBlockPattern.start()
                    .aisle("                                 ", "                                 ", "                                 ", "                                 ", "                                 ", "                                 ", "                                 ", "                                 ", "                                 ", "                                 ", "                                 ", "                                 ", "               A A               ", "               A A               ", "               A A               ", "            AAAAAAAAA            ", "               A A               ", "            AAAAAAAAA            ", "               A A               ", "               A A               ", "               A A               ", "                                 ", "                                 ", "                                 ", "                                 ", "                                 ", "                                 ", "                                 ", "                                 ", "                                 ", "                                 ", "                                 ", "                                 ")
                    .aisle("                                 ", "                                 ", "                                 ", "                                 ", "                                 ", "                                 ", "                                 ", "                                 ", "                                 ", "               A A               ", "               A A               ", "               A A               ", "               A A               ", "              DDDDD              ", "             DDADADD             ", "         AAAADAADAADAAAA         ", "             DDDDDDD             ", "         AAAADAADAADAAAA         ", "             DDADADD             ", "              DDDDD              ", "               A A               ", "               A A               ", "               A A               ", "               A A               ", "                                 ", "                                 ", "                                 ", "                                 ", "                                 ", "                                 ", "                                 ", "                                 ", "                                 ")
                    .aisle("                                 ", "                                 ", "                                 ", "                                 ", "                                 ", "                                 ", "                                 ", "               A A               ", "               A A               ", "               A A               ", "                D                ", "                D                ", "             DDDDDDD             ", "            DD     DD            ", "            D  EEE  D            ", "       AAA  D EFFFE D  AAA       ", "          DDD EFFFE DDD          ", "       AAA  D EFFFE D  AAA       ", "            D  EEE  D            ", "            DD     DD            ", "             DDDDDDD             ", "                D                ", "                D                ", "               A A               ", "               A A               ", "               A A               ", "                                 ", "                                 ", "                                 ", "                                 ", "                                 ", "                                 ", "                                 ")
                    .aisle("                                 ", "                                 ", "                                 ", "                                 ", "                                 ", "                                 ", "               A A               ", "               A A               ", "                D                ", "                D                ", "                                 ", "                                 ", "                                 ", "                                 ", "                                 ", "      AA                 AA      ", "        DD             DD        ", "      AA                 AA      ", "                                 ", "                                 ", "                                 ", "                                 ", "                                 ", "                D                ", "                D                ", "               A A               ", "               A A               ", "                                 ", "                                 ", "                                 ", "                                 ", "                                 ", "                                 ")
                    .aisle("                                 ", "                                 ", "                                 ", "                                 ", "                                 ", "               A A               ", "              AAAAA              ", "                D                ", "                F                ", "                F                ", "                                 ", "                                 ", "                                 ", "                                 ", "      A                   A      ", "     AA                   AA     ", "      ADFF             FFDA      ", "     AA                   AA     ", "      A                   A      ", "                                 ", "                                 ", "                                 ", "                                 ", "                F                ", "                F                ", "                D                ", "              AAAAA              ", "               A A               ", "                                 ", "                                 ", "                                 ", "                                 ", "                                 ")
                    .aisle("                                 ", "                                 ", "                                 ", "                                 ", "               A A               ", "               A A               ", "                D                ", "             GEEFEEG             ", "                                 ", "                                 ", "                                 ", "                                 ", "                                 ", "       G                 G       ", "       E                 E       ", "    AA E                 E AA    ", "      DF                 FD      ", "    AA E                 E AA    ", "       E                 E       ", "       G                 G       ", "                                 ", "                                 ", "                                 ", "                                 ", "                                 ", "             GEEFEEG             ", "                D                ", "               A A               ", "               A A               ", "                                 ", "                                 ", "                                 ", "                                 ")
                    .aisle("                                 ", "                                 ", "                                 ", "               A A               ", "              AAAAA              ", "                D                ", "                F                ", "                                 ", "                                 ", "                                 ", "                                 ", "                                 ", "                                 ", "                                 ", "    A                       A    ", "   AA                       AA   ", "    ADF                   FDA    ", "   AA                       AA   ", "    A                       A    ", "                                 ", "                                 ", "                                 ", "                                 ", "                                 ", "                                 ", "                                 ", "                F                ", "                D                ", "              AAAAA              ", "               A A               ", "                                 ", "                                 ", "                                 ")
                    .aisle("                                 ", "                                 ", "               A A               ", "               A A               ", "                D                ", "             GEEFEEG             ", "                                 ", "                                 ", "                                 ", "                                 ", "                                 ", "                                 ", "                                 ", "     G                     G     ", "     E                     E     ", "  AA E                     E AA  ", "    DF                     FD    ", "  AA E                     E AA  ", "     E                     E     ", "     G                     G     ", "                                 ", "                                 ", "                                 ", "                                 ", "                                 ", "                                 ", "                                 ", "             GEEFEEG             ", "                D                ", "               A A               ", "               A A               ", "                                 ", "                                 ")
                    .aisle("                                 ", "                                 ", "               A A               ", "                D                ", "                F                ", "                                 ", "                                 ", "                                 ", "                                 ", "                                 ", "                                 ", "                                 ", "                                 ", "                                 ", "                                 ", "  A                           A  ", "   DF                       FD   ", "  A                           A  ", "                                 ", "                                 ", "                                 ", "                                 ", "                                 ", "                                 ", "                                 ", "                                 ", "                                 ", "                                 ", "                F                ", "                D                ", "               A A               ", "                                 ", "                                 ")
                    .aisle("                                 ", "               A A               ", "               A A               ", "                D                ", "                F                ", "                                 ", "                                 ", "                                 ", "                                 ", "                                 ", "                                 ", "                                 ", "                                 ", "                                 ", "                                 ", " AA                           AA ", "   DF                       FD   ", " AA                           AA ", "                                 ", "                                 ", "                                 ", "                                 ", "                                 ", "                                 ", "                                 ", "                                 ", "                                 ", "                                 ", "                F                ", "                D                ", "               A A               ", "               A A               ", "                                 ")
                    .aisle("                                 ", "               A A               ", "                D                ", "                                 ", "                                 ", "                                 ", "                                 ", "                                 ", "                                 ", "                                 ", "                                 ", "                                 ", "                                 ", "                                 ", "                                 ", " A                             A ", "  D                           D  ", " A                             A ", "                                 ", "                                 ", "                                 ", "                                 ", "                                 ", "                                 ", "                                 ", "                                 ", "                                 ", "                                 ", "                                 ", "                                 ", "                D                ", "               A A               ", "                                 ")
                    .aisle("                                 ", "               A A               ", "                D                ", "                                 ", "                                 ", "                                 ", "                                 ", "                                 ", "                                 ", "                                 ", "                                 ", "                                 ", "                                 ", "                                 ", "                                 ", " A                             A ", "  D                           D  ", " A                             A ", "                                 ", "                                 ", "                                 ", "                                 ", "                                 ", "                                 ", "                                 ", "                                 ", "                                 ", "                                 ", "                                 ", "                                 ", "                D                ", "               A A               ", "                                 ")
                    .aisle("               A A               ", "               A A               ", "             DDDDDDD             ", "                                 ", "                                 ", "                                 ", "                                 ", "                                 ", "                                 ", "                                 ", "                                 ", "                                 ", "                                 ", "  D                           D  ", "  D                           D  ", "AAD                           DAA", "  D                           D  ", "AAD                           DAA", "  D                           D  ", "  D                           D  ", "                                 ", "                                 ", "                                 ", "                                 ", "                                 ", "                                 ", "                                 ", "                                 ", "                                 ", "                                 ", "             DDDDDDD             ", "               A A               ", "               A A               ")
                    .aisle("               A A               ", "              DDDDD              ", "            DD     DD            ", "                                 ", "                                 ", "       G                 G       ", "                                 ", "     G                     G     ", "                                 ", "                                 ", "                                 ", "                                 ", "  D                           D  ", "  D                           D  ", " D                             D ", "AD                             DA", " D                             D ", "AD                             DA", " D                             D ", "  D                           D  ", "  D                           D  ", "                                 ", "                                 ", "                                 ", "                                 ", "     G                     G     ", "                                 ", "       G                 G       ", "                                 ", "                                 ", "            DD     DD            ", "              DDDDD              ", "               A A               ")
                    .aisle("               A A               ", "             DDADADD             ", "            D  EEE  D            ", "                                 ", "      A                   A      ", "       E                 E       ", "    A                       A    ", "     E                     E     ", "                                 ", "                                 ", "                                 ", "                                 ", "  D                           D  ", " D                             D ", " D                             D ", "AAE                           EAA", " DE                           ED ", "AAE                           EAA", " D                             D ", " D                             D ", "  D                           D  ", "                                 ", "                                 ", "                                 ", "                                 ", "     E                     E     ", "    A                       A    ", "       E                 E       ", "      A                   A      ", "                                 ", "            D  EEE  D            ", "             DDADADD             ", "               A A               ")
                    .aisle("            AAAAAAAAA            ", "         AAAADAADAADAAAA         ", "       AAA  D EFFFE D  AAA       ", "      AA                 AA      ", "     AA                   AA     ", "    AA E                 E AA    ", "   AA                       AA   ", "  AA E                     E AA  ", "  A                           A  ", " AA                           AA ", " A                             A ", " A                             A ", "AAD                           DAA", "AD                             DA", "AAE                           EAA", "AAF                           FAA", "ADF                           FDA", "AAF                           FAA", "AAE                           EAA", "AD                             DA", "AAD                           DAA", " A                             A ", " A                             A ", " AA                           AA ", "  A                           A  ", "  AA E                     E AA  ", "   AA                       AA   ", "    AA E                 E AA    ", "     AA                   AA     ", "      AA                 AA      ", "       AAA  D EFFFE D  AAA       ", "         AAAADAADAADAAAA         ", "            AAAAAAAAA            ")
                    .aisle("               A A               ", "             DDDDDDD             ", "          DDD EFFFE DDD          ", "        DD             DD        ", "      ADFF             FFDA      ", "      DF                 FD      ", "    ADF                   FDA    ", "    DF                     FD    ", "   DF                       FD   ", "   DF                       FD   ", "  D                           D  ", "  D                           D  ", "  D                           D  ", " D                             D ", " DE                           ED ", "ADF                           FDA", " DF                           FD ", "ADF                           FDA", " DE                           ED ", " D                             D ", "  D                           D  ", "  D                           D  ", "  D                           D  ", "   DF                       FD   ", "   DF                       FD   ", "    DF                     FD    ", "    ADF                   FDA    ", "      DF                 FD      ", "      ADFF             FFDA      ", "        DD             DD        ", "          DDD EFFFE DDD          ", "             DDDDDDD             ", "               A A               ")
                    .aisle("            AAAAAAAAA            ", "         AAAADAADAADAAAA         ", "       AAA  D EFFFE D  AAA       ", "      AA                 AA      ", "     AA                   AA     ", "    AA E                 E AA    ", "   AA                       AA   ", "  AA E                     E AA  ", "  A                           A  ", " AA                           AA ", " A                             A ", " A                             A ", "AAD                           DAA", "AD                             DA", "AAE                           EAA", "AAF                           FAA", "ADF                           FDA", "AAF                           FAA", "AAE                           EAA", "AD                             DA", "AAD                           DAA", " A                             A ", " A                             A ", " AA                           AA ", "  A                           A  ", "  AA E                     E AA  ", "   AA                       AA   ", "    AA E                 E AA    ", "     AA                   AA     ", "      AA                 AA      ", "       AAA  D EFFFE D  AAA       ", "         AAAADAADAADAAAA         ", "            AAAAAAAAA            ")
                    .aisle("               A A               ", "             DDADADD             ", "            D  EEE  D            ", "                                 ", "      A                   A      ", "       E                 E       ", "    A                       A    ", "     E                     E     ", "                                 ", "                                 ", "                                 ", "                                 ", "  D                           D  ", " D                             D ", " D                             D ", "AAE                           EAA", " DE                           ED ", "AAE                           EAA", " D                             D ", " D                             D ", "  D                           D  ", "                                 ", "                                 ", "                                 ", "                                 ", "     E                     E     ", "    A                       A    ", "       E                 E       ", "      A                   A      ", "                                 ", "            D  EEE  D            ", "             DDADADD             ", "               A A               ")
                    .aisle("               A A               ", "              DDDDD              ", "            DD     DD            ", "                                 ", "                                 ", "       G                 G       ", "                                 ", "     G                     G     ", "                                 ", "                                 ", "                                 ", "                                 ", "  D                           D  ", "  D                           D  ", " D                             D ", "AD                             DA", " D                             D ", "AD                             DA", " D                             D ", "  D                           D  ", "  D                           D  ", "                                 ", "                                 ", "                                 ", "                                 ", "     G                     G     ", "                                 ", "       G                 G       ", "                                 ", "                                 ", "            DD     DD            ", "              DDDDD              ", "               A A               ")
                    .aisle("               A A               ", "               A A               ", "             DDDDDDD             ", "                                 ", "                                 ", "                                 ", "                                 ", "                                 ", "                                 ", "                                 ", "                                 ", "                                 ", "                                 ", "  D                           D  ", "  D                           D  ", "AAD                           DAA", "  D                           D  ", "AAD                           DAA", "  D                           D  ", "  D                           D  ", "                                 ", "                                 ", "                                 ", "                                 ", "                                 ", "                                 ", "                                 ", "                                 ", "                                 ", "                                 ", "             DDDDDDD             ", "               A A               ", "               A A               ")
                    .aisle("                                 ", "               A A               ", "                D                ", "                                 ", "                                 ", "                                 ", "                                 ", "                                 ", "                                 ", "                                 ", "                                 ", "                                 ", "                                 ", "                                 ", "                                 ", " A                             A ", "  D                           D  ", " A                             A ", "                                 ", "                                 ", "                                 ", "                                 ", "                                 ", "                                 ", "                                 ", "                                 ", "                                 ", "                                 ", "                                 ", "                                 ", "                D                ", "               A A               ", "                                 ")
                    .aisle("                                 ", "               A A               ", "                D                ", "                                 ", "                                 ", "                                 ", "                                 ", "                                 ", "                                 ", "                                 ", "                                 ", "                                 ", "                                 ", "                                 ", "                                 ", " A                             A ", "  D                           D  ", " A                             A ", "                                 ", "                                 ", "                                 ", "                                 ", "                                 ", "                                 ", "                                 ", "                                 ", "                                 ", "                                 ", "                                 ", "                                 ", "                D                ", "               A A               ", "                                 ")
                    .aisle("                                 ", "               A A               ", "               A A               ", "                D                ", "                F                ", "                                 ", "                                 ", "                                 ", "                                 ", "                                 ", "                                 ", "                                 ", "                                 ", "                                 ", "                                 ", " AA                           AA ", "   DF                       FD   ", " AA                           AA ", "                                 ", "                                 ", "                                 ", "                                 ", "                                 ", "                                 ", "                                 ", "                                 ", "                                 ", "                                 ", "                F                ", "                D                ", "               A A               ", "               A A               ", "                                 ")
                    .aisle("                                 ", "                                 ", "               A A               ", "                D                ", "                F                ", "                                 ", "                                 ", "                                 ", "                                 ", "                                 ", "                                 ", "                                 ", "                                 ", "                                 ", "                                 ", "  A                           A  ", "   DF                       FD   ", "  A                           A  ", "                                 ", "                                 ", "                                 ", "                                 ", "                                 ", "                                 ", "                                 ", "                                 ", "                                 ", "                                 ", "                F                ", "                D                ", "               A A               ", "                                 ", "                                 ")
                    .aisle("                                 ", "                                 ", "               A A               ", "               A A               ", "                D                ", "             GEEFEEG             ", "                                 ", "                                 ", "                                 ", "                                 ", "                                 ", "                                 ", "                                 ", "     G                     G     ", "     E                     E     ", "  AA E                     E AA  ", "    DF                     FD    ", "  AA E                     E AA  ", "     E                     E     ", "     G                     G     ", "                                 ", "                                 ", "                                 ", "                                 ", "                                 ", "                                 ", "                                 ", "             GEEFEEG             ", "                D                ", "               A A               ", "               A A               ", "                                 ", "                                 ")
                    .aisle("                                 ", "                                 ", "                                 ", "               A A               ", "              AAAAA              ", "                D                ", "                F                ", "                                 ", "                                 ", "                                 ", "                                 ", "                                 ", "                                 ", "                                 ", "    A                       A    ", "   AA                       AA   ", "    ADF                   FDA    ", "   AA                       AA   ", "    A                       A    ", "                                 ", "                                 ", "                                 ", "                                 ", "                                 ", "                                 ", "                                 ", "                F                ", "                D                ", "              AAAAA              ", "               A A               ", "                                 ", "                                 ", "                                 ")
                    .aisle("                                 ", "                                 ", "                                 ", "                                 ", "               A A               ", "               A A               ", "                D                ", "             GEEFEEG             ", "                                 ", "                                 ", "                                 ", "                                 ", "                                 ", "       G                 G       ", "       E                 E       ", "    AA E                 E AA    ", "      DF                 FD      ", "    AA E                 E AA    ", "       E                 E       ", "       G                 G       ", "                                 ", "                                 ", "                                 ", "                                 ", "                                 ", "             GEEFEEG             ", "                D                ", "               A A               ", "               A A               ", "                                 ", "                                 ", "                                 ", "                                 ")
                    .aisle("                                 ", "                                 ", "                                 ", "                                 ", "                                 ", "               A A               ", "              AAAAA              ", "                D                ", "                F                ", "                F                ", "                                 ", "                                 ", "                                 ", "                                 ", "      A                   A      ", "     AA                   AA     ", "      ADFF             FFDA      ", "     AA                   AA     ", "      A                   A      ", "                                 ", "                                 ", "                                 ", "                                 ", "                F                ", "                F                ", "                D                ", "              AAAAA              ", "               A A               ", "                                 ", "                                 ", "                                 ", "                                 ", "                                 ")
                    .aisle("                                 ", "                                 ", "                                 ", "                                 ", "                                 ", "                                 ", "               A A               ", "               A A               ", "                D                ", "                D                ", "                                 ", "                                 ", "                                 ", "                                 ", "                                 ", "      AA                 AA      ", "        DD             DD        ", "      AA                 AA      ", "                                 ", "                                 ", "                                 ", "                                 ", "                                 ", "                D                ", "                D                ", "               A A               ", "               A A               ", "                                 ", "                                 ", "                                 ", "                                 ", "                                 ", "                                 ")
                    .aisle("                                 ", "                                 ", "                                 ", "                                 ", "                                 ", "                                 ", "                                 ", "               A A               ", "               A A               ", "               A A               ", "                D                ", "                D                ", "             DDDDDDD             ", "            DD     DD            ", "            D  EEE  D            ", "       AAA  D EFFFE D  AAA       ", "          DDD EFFFE DDD          ", "       AAA  D EFFFE D  AAA       ", "            D  EEE  D            ", "            DD     DD            ", "             DDDDDDD             ", "                D                ", "                D                ", "               A A               ", "               A A               ", "               A A               ", "                                 ", "                                 ", "                                 ", "                                 ", "                                 ", "                                 ", "                                 ")
                    .aisle("                                 ", "                                 ", "                                 ", "                                 ", "                                 ", "                                 ", "                                 ", "                                 ", "                                 ", "               A A               ", "               A A               ", "               A A               ", "               A A               ", "              DDDDD              ", "             DDADADD             ", "         AAAADAADAADAAAA         ", "             DDDDDDD             ", "         AAAADAADAADAAAA         ", "             DDADADD             ", "              DDDDD              ", "               A A               ", "               A A               ", "               A A               ", "               A A               ", "                                 ", "                                 ", "                                 ", "                                 ", "                                 ", "                                 ", "                                 ", "                                 ", "                                 ")
                    .aisle("                                 ", "                                 ", "                                 ", "                                 ", "                                 ", "                                 ", "                                 ", "                                 ", "                                 ", "                                 ", "                                 ", "                                 ", "             AAAAAAA             ", "            AABBBBBAA            ", "            ABBBBBBBA            ", "            ABBAAABBA            ", "            ABBA~ABBA            ", "            ABBAAABBA            ", "            ABBBBBBBA            ", "            AABBBBBAA            ", "             AAAAAAA             ", "                                 ", "                                 ", "                                 ", "                                 ", "                                 ", "                                 ", "                                 ", "                                 ", "                                 ", "                                 ", "                                 ", "                                 ")
                    .where('~', Predicates.controller(Predicates.blocks(definition.get())))
                    .where('A', Predicates.blocks(GTOBlocks.DIMENSIONALLY_TRANSCENDENT_CASING.get()))
                    .where('B', Predicates.blocks(GTBlocks.HIGH_POWER_CASING.get())
                            .or(Predicates.abilities(PartAbility.EXPORT_ITEMS).setPreviewCount(1))
                            .or(Predicates.abilities(PartAbility.IMPORT_ITEMS).setPreviewCount(1))
                            .or(Predicates.abilities(PartAbility.EXPORT_FLUIDS).setPreviewCount(1))
                            .or(Predicates.abilities(PartAbility.IMPORT_FLUIDS).setPreviewCount(1)))
                    .where('D', Predicates.blocks(GTOBlocks.DIMENSION_INJECTION_CASING.get()))
                    .where('E', Predicates.blocks(GTOBlocks.DIMENSIONAL_BRIDGE_CASING.get()))
                    .where('F', Predicates.blocks(GTOBlocks.SPACETIME_COMPRESSION_FIELD_GENERATOR.get()))
                    .where('G', Predicates.blocks(GTOBlocks.DIMENSIONAL_STABILITY_CASING.get()))
                    .where(" ", Predicates.any())
                    .build())
            .renderer(EyeOfHarmonyRenderer::new)
            .hasTESR(true)
            .register();

    public final static MultiblockMachineDefinition SPACE_PROBE_SURFACE_RECEPTION = REGISTRATE.multiblock("space_probe_surface_reception", SpaceProbeSurfaceReceptionMachine::new)
            .rotationState(RotationState.NON_Y_AXIS)
            .allowExtendedFacing(false)
            .recipeType(GTORecipeTypes.SPACE_PROBE_SURFACE_RECEPTION_RECIPES)
            .tooltips(Component.translatable("gtocore.machine.space_probe_surface_reception.tooltip.0"))
            .tooltips(Component.translatable("gtceu.machine.perfect_oc"))
            .tooltips(Component.translatable("gtceu.machine.available_recipe_map_1.tooltip",
                    Component.translatable("gtceu.space_probe_surface_reception")))
            .recipeModifier(GTRecipeModifiers.ELECTRIC_OVERCLOCK.apply(OverclockingLogic.PERFECT_OVERCLOCK_SUBTICK))
            .appearanceBlock(GCyMBlocks.CASING_ATOMIC)
            .pattern(definition -> FactoryBlockPattern.start()
                    .aisle("                                     ", "                                     ", "                                     ", "                                     ", "                                     ", "                                     ", "                                     ", "                                     ", "                                     ", "                                     ", "                                     ", "                                     ", "                                     ", "                                     ", "                                     ", "                                     ", "                                     ", "                                     ", "                                     ", "                                     ", "                                     ", "                                     ", "                                     ", "                                     ", "                                     ", "                                     ", "                                     ", "                                     ", "                                     ", "                                     ")
                    .aisle("                                     ", "                                     ", "                                     ", "                                     ", "                                     ", "                                     ", "                                     ", "                                     ", "                                     ", "                                     ", "                                     ", "                                     ", "                                     ", "                                     ", "                                     ", "              AAAAAAAAA              ", "                                     ", "                                     ", "                                     ", "                                     ", "                                     ", "                                     ", "                                     ", "                                     ", "                                     ", "                                     ", "                                     ", "                                     ", "                                     ", "                                     ")
                    .aisle("                                     ", "                                     ", "                                     ", "                                     ", "                                     ", "                                     ", "                                     ", "                                     ", "                                     ", "                                     ", "                                     ", "                                     ", "                                     ", "                                     ", "                                     ", "          AAAAAAAAAAAAAAAAA          ", "                                     ", "                                     ", "                                     ", "                                     ", "                                     ", "                                     ", "                                     ", "                                     ", "                                     ", "                                     ", "                                     ", "                                     ", "                                     ", "                                     ")
                    .aisle("                 BBB                 ", "                                     ", "                                     ", "                                     ", "                                     ", "                                     ", "                                     ", "                                     ", "                                     ", "                                     ", "                                     ", "                                     ", "                                     ", "                                     ", "                                     ", "        AAAAAAAAAAAAAAAAAAAAA        ", "                                     ", "                                     ", "                                     ", "                                     ", "                                     ", "                                     ", "                                     ", "                                     ", "                                     ", "                                     ", "                                     ", "                                     ", "                                     ", "                                     ")
                    .aisle("                  B                  ", "                  B                  ", "                                     ", "                                     ", "                                     ", "                                     ", "                                     ", "                                     ", "                                     ", "                                     ", "                                     ", "                                     ", "                                     ", "                                     ", "           AAAAAAAAAAAAAAA           ", "       AAAA       C       AAAA       ", "                                     ", "                                     ", "                                     ", "                                     ", "                                     ", "                                     ", "                                     ", "                                     ", "                                     ", "                                     ", "                                     ", "                                     ", "                                     ", "                                     ")
                    .aisle("                                     ", "                  B                  ", "                  B                  ", "                                     ", "                                     ", "                                     ", "                                     ", "                                     ", "                                     ", "                                     ", "                                     ", "                                     ", "                                     ", "            AAAAAAAAAAAAA            ", "         AAA      C      AAA         ", "      AAA                   AAA      ", "                                     ", "                                     ", "                                     ", "                                     ", "                                     ", "                                     ", "                                     ", "                                     ", "                                     ", "                                     ", "                                     ", "                                     ", "                                     ", "                                     ")
                    .aisle("                                     ", "                                     ", "                  B                  ", "                  B                  ", "                                     ", "                                     ", "                                     ", "                                     ", "                                     ", "                                     ", "                                     ", "                                     ", "             AAAAAAAAAAA             ", "          AAA     C     AAA          ", "        AA                 AA        ", "     AAA          C          AAA     ", "                                     ", "                                     ", "                                     ", "                                     ", "                                     ", "                                     ", "                                     ", "                                     ", "                                     ", "                                     ", "                                     ", "                                     ", "                                     ", "                                     ")
                    .aisle("                                     ", "                                     ", "                                     ", "                  B                  ", "                BBBBB                ", "                  B                  ", "                                     ", "                                     ", "                                     ", "                                     ", "                                     ", "                                     ", "           AAAAAAAAAAAAAAA           ", "         AA       C       AA         ", "       AA                   AA       ", "    AAA                       AAA    ", "                  C                  ", "                                     ", "                                     ", "                                     ", "                                     ", "                                     ", "                                     ", "                                     ", "                                     ", "                                     ", "                                     ", "                                     ", "                                     ", "                                     ")
                    .aisle("                                     ", "                                     ", "                                     ", "                                     ", "                D   D                ", "                D B D                ", "           D             D           ", "           D             D           ", "          DD             DD          ", "          D               D          ", "         DD               DD         ", "         D    AAAAAAAAA    D         ", "        DBAAAA    C    AAAABD        ", "       BAA                 AAB       ", "      AA                     AA      ", "   AAA                         AAA   ", "                                     ", "                  C                  ", "                                     ", "                                     ", "                                     ", "                                     ", "                                     ", "                                     ", "                                     ", "                                     ", "                                     ", "                                     ", "                                     ", "                                     ")
                    .aisle("                                     ", "                                     ", "            B           B            ", "            B           B            ", "            DB          D            ", "            D    DBD    D            ", "            D    D D    D            ", "                                     ", "                  D                  ", "                                     ", "                                     ", "            AAAAAAAAAAAAA            ", "       DBAAA      C      AAABD       ", "       AA                   AA       ", "     AA                       AA     ", "  AAA                           AAA  ", "                                     ", "                                     ", "                  C                  ", "                                     ", "                                     ", "                                     ", "                                     ", "                                     ", "                                     ", "                                     ", "                                     ", "                                     ", "                                     ", "                                     ")
                    .aisle("                                     ", "             B         B             ", "             B         B             ", "                EEEEE                ", "            BB  EEEEE   B            ", "                  E                  ", "                  D                  ", "                  D                  ", "               FFFFFFF               ", "               FFFFFFF               ", "       D       CCCCCCC       D       ", "       D   AAAA   C   AAAA   D       ", "       BAAA       C       AAAB       ", "      AA                     AA      ", "    AA                         AA    ", "  AA                             AA  ", "                                     ", "                                     ", "                                     ", "                  C                  ", "                                     ", "                                     ", "                                     ", "                                     ", "                                     ", "                                     ", "                                     ", "                                     ", "                                     ", "                                     ")
                    .aisle("              B       B              ", "              B       B              ", "                  E                  ", "              EEEEEEEEE              ", "            BBEE     EE B            ", "                EEEEE                ", "                                     ", "                                     ", "       D     FFFFFFFFFFF     D       ", "       D     FFFFFFFFFFF     D       ", "       D     CCCCCCCCCCC     D       ", "          AAA     C     AAA          ", "       AAA                 AAA       ", "     AA                       AA     ", "    A                           A    ", " AAA                             AAA ", "                                     ", "                                     ", "                                     ", "                                     ", "                  C                  ", "                                     ", "                                     ", "                                     ", "                                     ", "                                     ", "                                     ", "                                     ", "                                     ", "                                     ")
                    .aisle("                                     ", "                                     ", "              EEEEEEEEE              ", "            GG         GG            ", "            GG         GG            ", "              EEEEEEEEE              ", "       D          E          D       ", "       D                     D       ", "       D    FFFFFFFFFFFFF    D       ", "            FFFFFFFFFFFFF            ", "            CCCCCCCCCCCCC            ", "         AAA             AAA         ", "      AAA                   AAA      ", "     A                         A     ", "   AA                           AA   ", " AA                               AA ", "                                     ", "                                     ", "                                     ", "                                     ", "                                     ", "                  C                  ", "                                     ", "                                     ", "                                     ", "                                     ", "                                     ", "                                     ", "                                     ", "                                     ")
                    .aisle("                                     ", "                                     ", "        B    EEHHHHHHHEE    B        ", "        B  GG           GG  B        ", "        DBBGG           GGBBD        ", "        D   GGEEE   EEEGG   D        ", "        D        EEE        D        ", "                                     ", "           FFFFIIIIIIIFFFF           ", "           FFFFIIIIIIIFFFF           ", "           CCCCCCCCCCCCCCC           ", "        AAA               AAA        ", "      AA                     AA      ", "    AA                         AA    ", "   A                             A   ", " AA                               AA ", "                                     ", "                                     ", "                                     ", "                                     ", "                                     ", "                                     ", "                  C                  ", "                                     ", "                                     ", "                                     ", "                                     ", "                                     ", "                                     ", "                                     ")
                    .aisle("                                     ", "         B                 B         ", "         B  EEJJJJJJJJJEE  B         ", "           G             G           ", "        BBBG             G  B        ", "            GG         GG            ", "              GEEEEEEEG              ", "                                     ", "          FFFDDDDDDDDDDDFFF          ", "          FFFDDDDDDDDDDDFFF          ", "          CCCCCCCCCCCCCCCCC          ", "        AA                 AA        ", "     AAA                     AAA     ", "    A                           A    ", "   A                             A   ", " AA                               AA ", "                                     ", "                                     ", "                                     ", "                                     ", "                                     ", "                                     ", "                CCCCC                ", "                                     ", "                                     ", "                                     ", "                                     ", "                                     ", "                                     ", "                                     ")
                    .aisle("          B               B          ", "          B               B          ", "           EEJJJJJJJJJJJEE           ", "          E               E          ", "          E               E          ", "           EE           EE           ", "             GGGEEEEEGGG             ", "                  E                  ", "          FFFDDDDDDDDDDDFFF          ", "          FFFDDDDDDDDDDDFFF          ", "          CCCCCCCCCCCCCCCCC          ", "       AAA                 AAA       ", "     AA                       AA     ", "    A                           A    ", "   A                             A   ", "AAA                               AAA", "                                     ", "                                     ", "                                     ", "                                     ", "                                     ", "                 CCC                 ", "               CCKKKCC               ", "                                     ", "                                     ", "                                     ", "                                     ", "                                     ", "                                     ", "                                     ")
                    .aisle("                                     ", "                                     ", "           EHJJJJJJJJJJJHE           ", "          E               E          ", "       B  E               E          ", "           EE           EE           ", "             EGG     GGE             ", "               GGEEEGG               ", "         FFFIDDFFFFFFFDDIFFF         ", "         FFFIDDFFFFFFFDDIFFF         ", "         CCCCCCCCCCCCCCCCCCC         ", "       AA                   AA       ", "     AA                       AA     ", "    A                           A    ", "   A                             A   ", "AAA                               AAA", "                                     ", "                                     ", "                                     ", "                                     ", "                                     ", "                CCDCC                ", "              CCKKKKKCC              ", "                                     ", "                                     ", "                                     ", "                                     ", "                                     ", "                                     ", "                                     ")
                    .aisle("                                     ", "                                     ", "           EHJJJJJJJJJJJHE           ", "         EE               EE         ", "      BD E                 E DB      ", "       D  EEE           EEE  D       ", "             EE       EE             ", "               GEEEEEG               ", "         FFFIDDFFFFFFFDDIFFF         ", "         FFFIDDFFFFFFFDDIFFF         ", "         CCCCCCCCCCCCCCCCCCC         ", "       AA                   AA       ", "     AA                       AA     ", "    A                           A    ", "   A                             A   ", "AAA                               AAA", "                                     ", "                                     ", "                                     ", "                                     ", "                  C                  ", "               CCDDDCC               ", "             CCKKKKKKKCC             ", "                                     ", "                                     ", "                                     ", "                                     ", "                                     ", "                                     ", "                                     ")
                    .aisle("                                  B  ", "                                     ", "           EHJJJJJJJJJJJHE           ", "         EE               EE         ", "      B  E                 E  B      ", "        D EE             EE D        ", "        D   EEE       EEE   D        ", "               EEEEEEE      D        ", "         FFFIDDFFFFFFFDDIFFF         ", "         FFFIDDFFFFFFFDDIFFF         ", "         CCCCCCCCCCCCCCCCCCC         ", "       AA                   AA       ", "     AA                       AA     ", "    A                           A    ", "   A                             A   ", "AAA                               AAA", "                                     ", "                                     ", "                                     ", "                                     ", "                 CCC                 ", "              CCDDDDDCC              ", "             CKKKKKKKKKC             ", "                  L                  ", "                  L                  ", "                                     ", "                                     ", "                                     ", "                                     ", "                                     ")
                    .aisle("  BB                             BB  ", "   BB                           BB   ", "    BB    EEHJJJJJJJJJJJHEE    BB    ", "     BB  EE       M       EE  BB     ", "      B  E        M        E  B      ", "      BBBEEE      M      EEEBBB      ", "         D EEEE   M   EEEE D         ", "         D    EEEEMEEEE    D         ", "        DFFFIDDFFFMFFFDDIFFFD        ", "         FFFIDDFFFMFFFDDIFFF         ", "         CCCCCCCCCCCCCCCCCCC         ", "       AACC               CCAA       ", "     AACCC                 CCCAA     ", "    ACC                       CCA    ", "   AC                           CA   ", "AAAC C                         C CAAA", "      C                       C      ", "       C                     C       ", "        C                   C        ", "         C                 C         ", "          C     CCCCC     C          ", "           C  CDDDDDDDC  C           ", "            CCKKKKKKKKKCC            ", "                 LLL                 ", "                 LLL                 ", "                  L                  ", "                  L                  ", "                  L                  ", "                  L                  ", "                  L                  ")
                    .aisle("                                  B  ", "                                     ", "           EHJJJJJJJJJJJHE           ", "         EE               EE         ", "      B  E                 E  B      ", "        D EE             EE D        ", "        D   EEE       EEE   D        ", "               EEEEEEE      D        ", "         FFFIDDFFFFFFFDDIFFF         ", "         FFFIDDFFFFFFFDDIFFF         ", "         CCCCCCCCCCCCCCCCCCC         ", "       AA                   AA       ", "     AA                       AA     ", "    A                           A    ", "   A                             A   ", "AAA                               AAA", "                                     ", "                                     ", "                                     ", "                                     ", "                 CCC                 ", "              CCDDDDDCC              ", "             CKKKKKKKKKC             ", "                  L                  ", "                  L                  ", "                                     ", "                                     ", "                                     ", "                                     ", "                                     ")
                    .aisle("                                     ", "                                     ", "           EHJJJJJJJJJJJHE           ", "         EE               EE         ", "      BD E                 E DB      ", "       D  EEE           EEE  D       ", "             EE       EE             ", "               GEEEEEG               ", "         FFFIDDFFFFFFFDDIFFF         ", "         FFFIDDFFFFFFFDDIFFF         ", "         CCCCCCCCCCCCCCCCCCC         ", "       AA                   AA       ", "     AA                       AA     ", "    A                           A    ", "   A                             A   ", "AAA                               AAA", "                                     ", "                                     ", "                                     ", "                                     ", "                  C                  ", "               CCDDDDC               ", "             CCKKKKKKKCC             ", "                                     ", "                                     ", "                                     ", "                                     ", "                                     ", "                                     ", "                                     ")
                    .aisle("                                     ", "                                     ", "           EHJJJJJJJJJJJHE           ", "          E               E          ", "       B  E               E          ", "           EE           EE           ", "             EGG     GGE             ", "               GGEEEGG               ", "         FFFIDDFFFFFFFDDIFFF         ", "         FFFIDDFFFFFFFDDIFFF         ", "         CCCCCCCCCCCCCCCCCCC         ", "       AA                   AA       ", "     AA                       AA     ", "    A                           A    ", "   A                             A   ", "AAA                               AAA", "                                     ", "                                     ", "                                     ", "                                     ", "                                     ", "                CCDCC                ", "              CCKKKKKCC              ", "                                     ", "                                     ", "                                     ", "                                     ", "                                     ", "                                     ", "                                     ")
                    .aisle("          B               B          ", "          B               B          ", "           EEJJJJJJJJJJJEE           ", "          E               E          ", "          E               E          ", "           EE           EE           ", "             GGGEEEEEGGG             ", "                  E                  ", "          FFFDDDDDDDDDDDFFF          ", "          FFFDDDDDDDDDDDFFF          ", "          CCCCCCCCCCCCCCCCC          ", "       AAA                 AAA       ", "     AA                       AA     ", "    A                           A    ", "   A                             A   ", "AAA                               AAA", "                                     ", "                                     ", "                                     ", "                                     ", "                                     ", "                 CCC                 ", "               CCKKKCC               ", "                                     ", "                                     ", "                                     ", "                                     ", "                                     ", "                                     ", "                                     ")
                    .aisle("                                     ", "         B                 B         ", "         B  bEJJJJJJJJJEb  B         ", "           G             G           ", "        B  G             G           ", "            GG         GG            ", "              GEEEEEEEG              ", "                                     ", "          FFFDDDDDDDDDDDFFF          ", "          FFFDDDDDDDDDDDFFF          ", "          CCCCCCCCCCCCCCCCC          ", "        AA                 AA        ", "     AAA                     AAA     ", "    A                           A    ", "   A                             A   ", " AA                               AA ", "                                     ", "                                     ", "                                     ", "                                     ", "                                     ", "                                     ", "                CCCCC                ", "                                     ", "                                     ", "                                     ", "                                     ", "                                     ", "                                     ", "                                     ")
                    .aisle("                                     ", "                                     ", "        B    bEHHHHHHHEb    B        ", "        B  GG           GG  B        ", "        DBBGG           GGBBD        ", "        D   GGEEE   EEEGG   D        ", "        D        EEE        D        ", "                                     ", "           FFFFIIIIIIIFFFF           ", "           FFFFIIIIIIIFFFF           ", "           CCCCCCCCCCCCCCC           ", "        AAA               AAA        ", "      AA                     AA      ", "    AA                         AA    ", "   A                             A   ", " AA                               AA ", "                                     ", "                                     ", "                                     ", "                                     ", "                                     ", "                                     ", "                  C                  ", "                                     ", "                                     ", "                                     ", "                                     ", "                                     ", "                                     ", "                                     ")
                    .aisle("                                     ", "                                     ", "              bbbbEbbbb              ", "            GG         GG            ", "            GG         GG            ", "              EEEEEEEEE              ", "       D          E          D       ", "       D                     D       ", "       D    FFFFFFFFFFFFF    D       ", "            FFFFFFFFFFFFF            ", "            CCCCCCCCCCCCC            ", "         AAA             AAA         ", "      AAA                   AAA      ", "     A                         A     ", "   AA                           AA   ", " AA                               AA ", "                                     ", "                                     ", "                                     ", "                                     ", "                                     ", "                  C                  ", "                                     ", "                                     ", "                                     ", "                                     ", "                                     ", "                                     ", "                                     ", "                                     ")
                    .aisle("              B       B              ", "              B       B              ", "                  ~                  ", "              EEEEEEEEE              ", "            B EE     EE B            ", "                EEEEE                ", "                                     ", "                                     ", "       D     FFFFFFFFFFF     D       ", "       D     FFFFFFFFFFF     D       ", "       D     CCCCCCCCCCC     D       ", "          AAA     C     AAA          ", "       AAA                 AAA       ", "     AA                       AA     ", "    A                           A    ", " AAA                             AAA ", "                                     ", "                                     ", "                                     ", "                                     ", "                  C                  ", "                                     ", "                                     ", "                                     ", "                                     ", "                                     ", "                                     ", "                                     ", "                                     ", "                                     ")
                    .aisle("                                     ", "             B         B             ", "             B         B             ", "                bbbbb                ", "            B   EEEEE   B            ", "                  E                  ", "                  D                  ", "                  D                  ", "               FFFFFFF               ", "               FFFFFFF               ", "       D       CCCCCCC       D       ", "       D   AAAA   C   AAAA   D       ", "       BAAA       C       AAAB       ", "      AA                     AA      ", "    AA                         AA    ", "  AA                             AA  ", "                                     ", "                                     ", "                                     ", "                  C                  ", "                                     ", "                                     ", "                                     ", "                                     ", "                                     ", "                                     ", "                                     ", "                                     ", "                                     ", "                                     ")
                    .aisle("                                     ", "                                     ", "            B           B            ", "            B           B            ", "            D          BD            ", "            D    DBD    D            ", "            D    D D    D            ", "                 D D                 ", "                  D                  ", "                                     ", "                                     ", "            AAAAAAAAAAAAA            ", "       DBAAA      C      AAABD       ", "       AA                   AA       ", "     AA                       AA     ", "  AAA                           AAA  ", "                                     ", "                                     ", "                  C                  ", "                                     ", "                                     ", "                                     ", "                                     ", "                                     ", "                                     ", "                                     ", "                                     ", "                                     ", "                                     ", "                                     ")
                    .aisle("                                     ", "                                     ", "                                     ", "                                     ", "                D   D                ", "                D B D                ", "           D             D           ", "           D             D           ", "          DD             DD          ", "          D               D          ", "         DD               DD         ", "         D    AAAAAAAAA    D         ", "        DBAAAA    C    AAAABD        ", "       BAA                 AAB       ", "      AA                     AA      ", "   AAA                         AAA   ", "                                     ", "                  C                  ", "                                     ", "                                     ", "                                     ", "                                     ", "                                     ", "                                     ", "                                     ", "                                     ", "                                     ", "                                     ", "                                     ", "                                     ")
                    .aisle("                                     ", "                                     ", "                                     ", "                  B                  ", "                BBBBB                ", "                  B                  ", "                                     ", "                                     ", "                                     ", "                                     ", "                                     ", "                                     ", "           AAAAAAAAAAAAAAA           ", "         AA       C       AA         ", "       AA                   AA       ", "    AAA                       AAA    ", "                  C                  ", "                                     ", "                                     ", "                                     ", "                                     ", "                                     ", "                                     ", "                                     ", "                                     ", "                                     ", "                                     ", "                                     ", "                                     ", "                                     ")
                    .aisle("                                     ", "                                     ", "                  B                  ", "                  B                  ", "                                     ", "                                     ", "                                     ", "                                     ", "                                     ", "                                     ", "                                     ", "                                     ", "             AAAAAAAAAAA             ", "          AAA     C     AAA          ", "        AA                 AA        ", "     AAA          C          AAA     ", "                                     ", "                                     ", "                                     ", "                                     ", "                                     ", "                                     ", "                                     ", "                                     ", "                                     ", "                                     ", "                                     ", "                                     ", "                                     ", "                                     ")
                    .aisle("                                     ", "                  B                  ", "                  B                  ", "                                     ", "                                     ", "                                     ", "                                     ", "                                     ", "                                     ", "                                     ", "                                     ", "                                     ", "                                     ", "            AAAAAAAAAAAAA            ", "         AAA      C      AAA         ", "      AAA                   AAA      ", "                                     ", "                                     ", "                                     ", "                                     ", "                                     ", "                                     ", "                                     ", "                                     ", "                                     ", "                                     ", "                                     ", "                                     ", "                                     ", "                                     ")
                    .aisle("                  B                  ", "                  B                  ", "                                     ", "                                     ", "                                     ", "                                     ", "                                     ", "                                     ", "                                     ", "                                     ", "                                     ", "                                     ", "                                     ", "                                     ", "           AAAAAAAAAAAAAAA           ", "       AAAA       C       AAAA       ", "                                     ", "                                     ", "                                     ", "                                     ", "                                     ", "                                     ", "                                     ", "                                     ", "                                     ", "                                     ", "                                     ", "                                     ", "                                     ", "                                     ")
                    .aisle("                 BBB                 ", "                                     ", "                                     ", "                                     ", "                                     ", "                                     ", "                                     ", "                                     ", "                                     ", "                                     ", "                                     ", "                                     ", "                                     ", "                                     ", "                                     ", "        AAAAAAAAAAAAAAAAAAAAA        ", "                                     ", "                                     ", "                                     ", "                                     ", "                                     ", "                                     ", "                                     ", "                                     ", "                                     ", "                                     ", "                                     ", "                                     ", "                                     ", "                                     ")
                    .aisle("                                     ", "                                     ", "                                     ", "                                     ", "                                     ", "                                     ", "                                     ", "                                     ", "                                     ", "                                     ", "                                     ", "                                     ", "                                     ", "                                     ", "                                     ", "          AAAAAAAAAAAAAAAAA          ", "                                     ", "                                     ", "                                     ", "                                     ", "                                     ", "                                     ", "                                     ", "                                     ", "                                     ", "                                     ", "                                     ", "                                     ", "                                     ", "                                     ")
                    .aisle("                                     ", "                                     ", "                                     ", "                                     ", "                                     ", "                                     ", "                                     ", "                                     ", "                                     ", "                                     ", "                                     ", "                                     ", "                                     ", "                                     ", "                                     ", "              AAAAAAAAA              ", "                                     ", "                                     ", "                                     ", "                                     ", "                                     ", "                                     ", "                                     ", "                                     ", "                                     ", "                                     ", "                                     ", "                                     ", "                                     ", "                                     ")
                    .where("~", Predicates.controller(Predicates.blocks(definition.get())))
                    .where("A", Predicates.blocks(ChemicalHelper.getBlock(TagPrefix.block, GTMaterials.Neutronium)))
                    .where("B", Predicates.blocks(GTOBlocks.NAQUADAH_REINFORCED_PLANT_CASING.get()))
                    .where("C", Predicates.blocks(GTOBlocks.HIGH_PRESSURE_RESISTANT_CASING.get()))
                    .where("D", Predicates.blocks(ChemicalHelper.getBlock(TagPrefix.frameGt, GTMaterials.Neutronium)))
                    .where("E", Predicates.blocks(GCyMBlocks.CASING_ATOMIC.get()))
                    .where("F", Predicates.blocks(GTOBlocks.HYPER_MECHANICAL_CASING.get()))
                    .where("G", Predicates.blocks(GTOBlocks.NEUTRONIUM_STABLE_CASING.get()))
                    .where("H", Predicates.blocks(GTOBlocks.HYPER_CORE.get()))
                    .where("I", Predicates.blocks(GCyMBlocks.HEAT_VENT.get()))
                    .where("J", Predicates.blocks(GTOBlocks.ANTIFREEZE_HEATPROOF_MACHINE_CASING.get()))
                    .where("K", Predicates.blocks(GTBlocks.HIGH_POWER_CASING.get()))
                    .where("L", Predicates.blocks(ChemicalHelper.getBlock(TagPrefix.frameGt, GTOMaterials.BlackTitanium)))
                    .where("M", Predicates.blocks(GTOBlocks.NEUTRONIUM_ACTIVE_CASING.get()))
                    .where("b", Predicates.blocks(GCyMBlocks.CASING_ATOMIC.get())
                            .or(Predicates.autoAbilities(definition.getRecipeTypes()))
                            .or(Predicates.abilities(PartAbility.MAINTENANCE).setExactLimit(1))
                            .or(Predicates.abilities(PartAbility.COMPUTATION_DATA_RECEPTION).setExactLimit(1)))
                    .where(" ", Predicates.any())
                    .build())
            .workableCasingRenderer(GTCEu.id("block/casings/gcym/atomic_casing"), GTCEu.id("block/multiblock/data_bank"))
            .register();

    public final static MultiblockMachineDefinition DIMENSIONALLY_TRANSCENDENT_PLASMA_FORGE = REGISTRATE.multiblock("dimensionally_transcendent_plasma_forge", DimensionallyTranscendentPlasmaForgeMachine::new)
            .rotationState(RotationState.NON_Y_AXIS)
            .allowExtendedFacing(false)
            .recipeType(GTORecipeTypes.DIMENSIONALLY_TRANSCENDENT_PLASMA_FORGE_RECIPES)
            .recipeType(GTORecipeTypes.STELLAR_FORGE_RECIPES)
